Workbook

Sheet CashFlow
B2: CURRENT - Statement of Cash Flow | I2: Revised - Statement of Cash Flow
B3: As of June 2025 | I3: As of 31 December 2024
B4: CASH INFLOWS | I4: CASH INFLOWS | J4: Self | K4: Spouse | L4: Combined | M4: Monthly
B5: Inflow (I) | C5: Self (A) | D5: Spouse (B) | E5: Combined (A+B) | F5: Monthly
B6: Gross Annual Income | C6: =4500*12 -> 54000 | D6: =4500*12 -> 54000 | E6: =SUM(C6:D6) -> 108000 | F6: =E6/12 -> 9000 | I6: Gross Annual Income | J6: 600000 | K6: 600000 | L6: =SUM(J6:K6) -> 1200000
B7: Gross Annual Employment Bonus | E7: =SUM(C7:D7) -> 0 | F7: =E7/12 -> 0 | I7: Gross Annual Employment Bonus | J7: 200000 | K7: 100000 | L7: =SUM(J7:K7) -> 300000
B8: EPF From Employer | C8: =C6*0.13 -> 7020 | D8: =D6*0.13 -> 7020 | E8: =SUM(C8:D8) -> 14040 | F8: =E8/12 -> 1170 | I8: EPF From Employer | J8: 72000 | K8: 72000 | L8: =SUM(J8:K8) -> 144000
B9: Sub Total | C9: =SUM(C6:C8) -> 61020 | D9: =SUM(D6:D8) -> 61020 | E9: =SUM(E6:E8) -> 122040 | F9: =E9/12 -> 10170 | I9: Sub Total | J9: =SUM(J6:J8) -> 872000 | K9: =SUM(K6:K8) -> 772000 | L9: =SUM(L6:L8) -> 1644000
B10: (Less EPF Of Employee) | C10: =C6*0.11 -> 5940 | D10: =D6*0.11 -> 5940 | E10: =SUM(C10:D10) -> 11880 | F10: =E10/12 -> 990 | I10: (Less EPF Of Employee) | J10: 66000 | K10: 66000 | L10: =SUM(J10:K10) -> 132000
B11: (Less EPF Of Employer) | C11: =C6*0.13 -> 7020 | D11: =D6*0.13 -> 7020 | E11: =SUM(C11:D11) -> 14040 | F11: =E11/12 -> 1170 | I11: (Less EPF Of Employer) | J11: 72000 | K11: 72000 | L11: =SUM(J11:K11) -> 144000
B12: (Less SOCSO) | C12: =22.25*12 -> 267 | D12: =22.25*12 -> 267 | E12: =SUM(C12:D12) -> 534 | F12: =E12/12 -> 44.5 | I12: (Less SOCSO) | J12: 350 | K12: 350 | L12: =SUM(J12:K12) -> 700
B13: Net Annual Income & Bonus | C13: =C9-SUM(C10:C12) -> 47793 | D13: =D9-SUM(D10:D12) -> 47793 | E13: =E9-SUM(E10:E12) -> 95586 | F13: =E13/12 -> 7965.5 | I13: Net Annual Income & Bonus | J13: =J9-SUM(J10:J12) -> 733650 | K13: =K9-SUM(K10:K12) -> 633650 | L13: =L9-SUM(L10:L12) -> 1367300 | M13: =L13/12 -> 113941.67
B14: Annual Interest Income (FD) | C14: - | D14: - | E14: =SUM(C14:D14) -> 0 | F14: =E14/12 -> 0 | I14: Annual Interest Income (FD) | J14: 20000 | K14: 15000 | L14: =SUM(J14:K14) -> 35000
B15: Annual Rental Income | C15: =(1000*12)+(8500*0.58*12)+(45000*0.1291*12) -> 140874 | D15: - | E15: =SUM(C15:D15) -> 140874 | F15: =E15/12 -> 11739.5 | I15: Annual Rental Income | J15: 88800 | K15: 42000 | L15: =SUM(J15:K15) -> 130800
B16: Annual Dividends (Shares) | C16: - | D16: - | E16: =SUM(C16:D16) -> 0 | F16: =E16/12 -> 0 | I16: Annual Dividends (Shares) | J16: 4500 | K16: - | L16: =SUM(J16:K16) -> 4500
B17: Total Inflow | C17: =SUM(C13:C16) -> 188667 | D17: =SUM(D13:D16) -> 47793 | E17: =SUM(E13:E16) -> 236460 | F17: =E17/12 -> 19705 | I17: Total Inflow | J17: =SUM(J13:J16) -> 846950 | K17: =SUM(K13:K16) -> 690650 | L17: =SUM(L13:L16) -> 1537600 | M17: =L17/12 -> 128133.33
B18: CASH OUTFLOWS
B19: Fixed Outflow (II.I) | C19: Self (A) | D19: Spouse (B) | E19: Combined (A+B) | F19: Monthly | I19: Fixed Outflow
B20: Resident Home Mortgage | C20: =(Loan!H11)*12 -> 0 | D20: - | E20: =SUM(C20:D20) -> 0 | F20: =E20/12 -> 0 | G20: =E20-L20 -> -33468 | I20: Resident Home Mortgage (Refinancing) | J20: 33468 | K20: - | L20: =SUM(J20:K20) -> 33468
B21: Investment Property Mortgage | C21: - | D21: - | E21: =SUM(C21:D21) -> 0 | F21: =E21/12 -> 0 | G21: =E21-L21 -> -95928 | I21: Investment Property Mortgage (Refinancing) | J21: 95928 | K21: - | L21: =SUM(J21:K21) -> 95928
B22: Car Loan Repayment | C22: =(Loan!P11)*12 -> 0 | D22: - | E22: =SUM(C22:D22) -> 0 | F22: =E22/12 -> 0 | I22: Car Loan Repayment | J22: 51300 | K22: - | L22: =SUM(J22:K22) -> 51300
B23: Savings & Investment | C23: - | D23: - | E23: =SUM(C23:D23) -> 0 | F23: =E23/12 -> 0 | G23: =E23-L23 -> -160000 | I23: Savings & Investment (Revised - To PRS) | J23: =100000 -> 100000 | K23: =60000 -> 60000 | L23: =SUM(J23:K23) -> 160000
B24: Vehicle (Car Maintenance, Road Tax, Insurance) | C24: 5000 | D24: - | E24: =SUM(C24:D24) -> 5000 | F24: =E24/12 -> 416.66667 | I24: Vehicle (Car Maintenance, Road Tax, Insurance) | J24: 5000 | K24: - | L24: =SUM(J24:K24) -> 5000
B25: Insurance | C25: =Coverage!J6 -> 21269.52 | D25: - | E25: =SUM(C25:D25) -> 21269.52 | F25: =E25/12 -> 1772.46 | I25: Insurance | J25: 54200 | K25: 30588 | L25: =SUM(J25:K25) -> 84788
B26: Insurance Premium for Medical | C26: =Coverage!J9 -> 6800 | D26: =Coverage!J13 -> 5900 | E26: =SUM(C26:D26) -> 12700 | F26: =E26/12 -> 1058.3333 | I26: Insurance Premium for Medical | J26: 6000 | K26: 6000 | L26: =SUM(J26:K26) -> 12000
B27: Insurance (Children) | C27: - | D27: - | E27: =SUM(C27:D27) -> 0 | F27: =E27/12 -> 0 | I27: Insurance (Children) | J27: 148000 | K27: - | L27: =SUM(J27:K27) -> 148000
B28: Total Fixed Outflow | C28: =SUM(C20:C27) -> 33069.52 | D28: =SUM(D20:D27) -> 5900 | E28: =SUM(E20:E27) -> 38969.52 | F28: =E28/12 -> 3247.46 | G28: =E28-L28 -> -551514.48 | I28: Total Fixed Outflow | J28: =SUM(J20:J27) -> 493896 | K28: =SUM(K20:K27) -> 96588 | L28: =SUM(L20:L27) -> 590484 | M28: =L28/12 -> 49207
B29: Variable Outflow (II.II) | C29: Self (A) | D29: Spouse (B) | E29: Combined (A+B) | F29: Monthly | I29: Variable Outflow
B30: Food | C30: =150*30*12 -> 54000 | D30: - | E30: =SUM(C30:D30) -> 54000 | F30: =E30/12 -> 4500 | G30: =E30-L30 -> 14000 | I30: Food | J30: 40000 | K30: - | L30: =SUM(J30:K30) -> 40000
B31: Clothing | C31: 1000 | D31: 1000 | E31: =SUM(C31:D31) -> 2000 | F31: =E31/12 -> 166.66667 | G31: =E31-L31 -> -3000 | I31: Clothing | J31: 5000 | K31: - | L31: =SUM(J31:K31) -> 5000
B32: Utilities & Telephone | C32: =300*12 -> 3600 | D32: =100*12 -> 1200 | E32: =SUM(C32:D32) -> 4800 | F32: =E32/12 -> 400 | G32: =E32-L32 -> 2300 | I32: Utilities & Telephone | J32: 2500 | K32: - | L32: =SUM(J32:K32) -> 2500
B33: Entertainment | C33: 2000 | D33: 2000 | E33: =SUM(C33:D33) -> 4000 | F33: =E33/12 -> 333.33333 | G33: =E33-L33 -> -24000 | I33: Entertainment | J33: 18000 | K33: 10000 | L33: =SUM(J33:K33) -> 28000
B34: Children’s Maintenance | C34: - | D34: - | E34: =SUM(C34:D34) -> 0 | F34: =E34/12 -> 0 | G34: =E34-L34 -> -30000 | I34: Children’s Maintenance | J34: 30000 | K34: - | L34: =SUM(J34:K34) -> 30000
B35: Parent Allowance | C35: =3500*12 -> 42000 | D35: - | E35: =SUM(C35:D35) -> 42000 | F35: =E35/12 -> 3500 | G35: =E35-L35 -> 32000 | I35: Parent Allowance | J35: 10000 | K35: - | L35: =SUM(J35:K35) -> 10000
B36: Vacations | C36: 50000 | D36: - | E36: =SUM(C36:D36) -> 50000 | F36: =E36/12 -> 4166.6667 | G36: =E36-L36 -> 0 | I36: Vacations | J36: 50000 | K36: - | L36: =SUM(J36:K36) -> 50000
B37: Income Tax | C37: 305 | D37: 305 | E37: =SUM(C37:D37) -> 610 | F37: =E37/12 -> 50.833333 | G37: =E37-L37 -> -245696 | I37: Income Tax (Revised) | J37: 134697 | K37: 111609 | L37: =SUM(J37:K37) -> 246306
B38: Total Variable Outflow | C38: =SUM(C30:C37) -> 152905 | D38: =SUM(D30:D37) -> 4505 | E38: =SUM(E30:E37) -> 157410 | F38: =E38/12 -> 13117.5 | G38: =E38-L38 -> -254396 | I38: Total Variable Outflow | J38: =SUM(J30:J37) -> 290197 | K38: =SUM(K30:K37) -> 121609 | L38: =SUM(L30:L37) -> 411806 | M38: =L38/12 -> 34317.167
B39: Total Cash Outflow (II.I + II.II) | C39: =SUM(C38,C28) -> 185974.52 | D39: =SUM(D38,D28) -> 10405 | E39: =SUM(E38,E28) -> 196379.52 | F39: =E39/12 -> 16364.96 | G39: =E39-L39 -> -805910.48 | I39: Total Cash Outflow | J39: =SUM(J38,J28) -> 784093 | K39: =SUM(K38,K28) -> 218197 | L39: =SUM(L38,L28) -> 1002290 | M39: =L39/12 -> 83524.167
B40: Net Cash Flow (Surplus) (I - II) | C40: =C17-C39 -> 2692.48 | D40: =D17-D39 -> 37388 | E40: =E17-E39 -> 40080.48 | F40: =E40/12 -> 3340.04 | G40: =E40-L40 -> -495229.52 | I40: Net Cash Flow (Surplus) | J40: =J17-J39 -> 62857 | K40: =K17-K39 -> 472453 | L40: =L17-L39 -> 535310 | M40: =L40/12 -> 44609.167
C42: 50000 | D42: 470000 | F42: Saving | G42: =SUM(G20:G21,G37) -> -375092 | J42: =J40-C40 -> 60164.52 | K42: =K40-D40 -> 435065 | L42: =L40-E40 -> 495229.52
...

Sheet Net Worth
B2: Statement of Net Worth | G2: Liabilities | H2: Rate | I2: Self | J2: Spouse | K2: Combined | L2: Monthly Payment | M2: Outstanding Balance
B3: As of June 2025
B4: ASSET | C4: Self (A) | D4: Spouse (B) | E4: Combined (A+B) | H4: % | I4: RM | J4: RM | K4: RM | L4: RM | M4: RM
B5: Cash / Cash Equivalent | C5: RM | D5: RM | E5: RM | G5: Current Liabilities
B6: Saving Account | C6: =2969+5735+153612+30616+5557+884+(12689+3992+22284)+((39189+3800+3000)*3.3)+((110000+3398+29330)*0.6)+(9949141*0.14) -> 1868618.2 | D6: =(1286308*0.13)+((62238+283542)*0.6) -> 374688.04 | E6: =SUM(C6:D6) -> 2243306.3 | G6: Income Tax Payable | I6: 305 | J6: 305 | K6: =SUM(I6:J6) -> 610
B7: Current Account | E7: =SUM(C7:D7) -> 0 | G7: Total Current Liability | I7: =SUM(I6) -> 305 | J7: =SUM(J6) -> 305 | K7: =SUM(K6) -> 610 | M7: =K7 -> 610
B8: Fixed Deposit | E8: =SUM(C8:D8) -> 0
B9: Life Insurance Cash Value | C9: =(1000000*0.6)+(36000+200000)+20000 -> 856000 | E9: =SUM(C9:D9) -> 856000 | G9: Long Term Liabilities
B10: Children Saving Account | E10: =SUM(C10:D10) -> 0 | G10: Residential Home Loan
B11: Total Cash & Cash Equivalent | C11: =SUM(C6:C10) -> 2724618.2 | D11: =SUM(D6:D10) -> 374688.04 | E11: =SUM(E6:E10) -> 3099306.3 | G11: Car Loan
B12: Investment Asset
B13: Equities (Stocks & Shares) | C13: =(((880*118.4)+(15480*5.78)+(1200*143.8))*0.54)+((301*22.11*4.24))+(107000) -> 332979.92 | D13: =(2000*1.43)+(1000*5.42)+(1000*0.09)+(2000*0.87)+(2000*6.9)+(166*0.1)+(5000*1.3)+(5000*1.9)+(10300*0.47)+(5000*1.15)+(1000*9.7)+(10*0.615)+(12*0.165)+(2000*0.055)+(33*0.09)+(4612*1.78)+(6000*1.49)+(7291*0.245)+(5277*0.005)+(15159*0.305)+(7000*0.04)+(7000*0.295)+(4000*0.045)+(375*0.54)+(3000*1.72)+(100*0.205)+(4000*0.26)+(9000*0.97)+(1200*0.07)+(200*0.065)+(300*0.105)+(800*0.1) -> 101810.74 | E13: =SUM(C13:D13) -> 434790.66 | G13: Total Long Term Liabilities | I13: =SUM(I10:I12) -> 0 | J13: =SUM(J10:J12) -> 0 | K13: =SUM(K10:K12) -> 0 | M13: =SUM(M10:M12) -> 0
B14: Bonds / Fixed Income | C14: =2267301*0.14 -> 317422.14 | E14: =SUM(C14:D14) -> 317422.14
B15: Unit Trust | C15: =129765.68+819381.38+94581+(57951+46995+50855+47711)+(197675+159503) -> 1604418.1 | E15: =SUM(C15:D15) -> 1604418.1 | G15: Total Liabilities | I15: =SUM(I7,I13) -> 305 | J15: =SUM(J7,J13) -> 305 | K15: =SUM(K7,K13) -> 610 | M15: =SUM(M13,M7) -> 610
B16: Investment Linked Policies | C16: =155445+150675+35801+34922+((471112+33461)*0.6) -> 679586.8 | D16: =(119562*0.6) -> 71737.2 | E16: =SUM(C16:D16) -> 751324 | G16: Net Worth (Total Asset – Total Liabilities) | M16: =E29-M15 -> 17263140
B17: EPF / APF | C17: =472367.7+40958 -> 513325.7 | D17: 188639 | E17: =SUM(C17:D17) -> 701964.7
B18: Other Retirement Account Balance | C18: =79987 -> 79987 | D18: =57337 -> 57337 | E18: =SUM(C18:D18) -> 137324
B19: Property | E19: =SUM(C19:D19) -> 0
B20: Others (Children ILP) | E20: =SUM(C20:D20) -> 0 | G20: Equities (Stock & Shares) | H20: Unit | I20: Price | J20: Total
B21: Total Investment Assets | C21: =SUM(C13:C20) -> 3527719.6 | D21: =SUM(D13:D20) -> 419523.93 | E21: =SUM(E13:E20) -> 3947243.6 | J21: =H21*I21 -> 0
B22: Personal Used Assets | J22: =H22*I22 -> 0
B23: Owner Occupied Property | C23: =I57 -> 8150000 | D23: =J57 -> 1897200 | E23: =SUM(C23:D23) -> 10047200 | J23: =H23*I23 -> 0
B24: Home Furnishing | E24: =SUM(C24:D24) -> 0 | J24: =H24*I24 -> 0
B25: Cars | C25: =I49 -> 150000 | D25: =J49 -> 20000 | E25: =SUM(C25:D25) -> 170000 | J25: =H25*I25 -> 0
B26: Jewelry / Collections | E26: =SUM(C26:D26) -> 0 | J26: =H26*I26 -> 0
B27: Others | D27: - | E27: =SUM(C27:D27) -> 0 | J27: =H27*I27 -> 0
B28: Total Used Assets | C28: =SUM(C23:C27) -> 8300000 | D28: =SUM(D23:D27) -> 1917200 | E28: =SUM(E23:E27) -> 10217200 | J28: =H28*I28 -> 0
B29: Total Assets | C29: =SUM(C11,C21,C28) -> 14552338 | D29: =SUM(D11,D21,D28) -> 2711412 | E29: =SUM(E11,E21,E28) -> 17263750 | J29: =H29*I29 -> 0
G32: Bond / Fixed Income | H32: Total
G36: Unit Trust | H36: Total
G39: Investment Linked Policies (ILP) | H39: Total
G43: PRS | H43: Total
G46: Property / Car | H46: Total | I46: Self | J46: Spouse
G47: Volvo CX90 2016 | H47: =SUM(I47:J47) -> 150000 | I47: 150000
G48: Myvi 2015 | H48: =SUM(I48:J48) -> 20000 | J48: 20000
G49: Total | H49: =SUM(H39:H48) -> 170000 | I49: =SUM(I39:I48) -> 150000 | J49: =SUM(J39:J48) -> 20000
G50: Gurney Beach Resort - 13D | H50: =SUM(I50:J50) -> 2000000 | I50: 2000000
G51: University Heights - 97-14-4 | H51: =SUM(I51:J51) -> 450000 | I51: 450000
G52: Lakeside Towers - 31-10-09 | H52: =SUM(I52:J52) -> 450000 | I52: 450000
G53: LUME - 13-6 | H53: =SUM(I53:J53) -> 900000 | I53: =1800000/2 -> 900000
...

Sheet Loan
B2: DEBT – House Mortgage Management (Residential) | J2: DEBT – Car Loan
E3: n | F3: i | G3: PV | H3: PMT | M3: n | N3: i | O3: PV | P3: PMT
C4: Housing Loan | D4: 0 | K4: Car Loan | L4: 0
C5: Interest | D5: 0.044 | K5: Interest | L5: 0.03
C6: Term of Loan -Years | D6: 40 | K6: Term of Loan -Years | L6: 9
C7: Loan Paid - Years | D7: 7 | K7: Loan Paid - Years | L7: 2
C8: Balance of Term after paying n years | D8: =D6-D7 -> 33 | K8: Balance of Term after paying n years | L8: =L6-L7 -> 7
C9: Refinance Interest Rate | D9: 0.038 | K9: Refinance Interest Rate | L9: 0.02
B11: 1 | C11: Monthly Instalment | E11: =D6 -> 40 | F11: =D5 -> 0.044 | G11: =D4 -> 0 | H11: =PMT(F11/12,E11*12,-G11) -> 0 | J11: 1 | K11: Monthly Instalment | M11: =L6 -> 9 | N11: =L5 -> 0.03 | O11: =L4 -> 0 | P11: =P13/(L6*12) -> 0
B12: 2 | C12: Total Interest | H12: =H13-D4 -> 0 | J12: 2 | K12: Total Interest | P12: =L4*L5*L6 -> 0
B13: 3 | C13: Total Loan | H13: =H11*E11*12 -> 0 | J13: 3 | K13: Total Loan | P13: =L4+P12 -> 0
B14: 4 | C14: Balance of Loan after n years | G14: =-FV(F11/12,D7*12,-H11,D4) -> 0 | J14: 4 | K14: Balance of Loan after n years | O14: =L4-((L4/L6)*L7) -> 0
B16: 5 | C16: Refinancing Monthly Instalment | E16: =D6-D7 -> 33 | F16: =D9 -> 0.038 | G16: =G14 -> 0 | H16: =PMT(D9/12,D8*12,-G16) -> 0 | J16: 5 | K16: Refinancing Monthly Instalment | M16: =L8 -> 7 | N16: =L9 -> 0.02 | O16: =O14 -> 0 | P16: =(O16+(O16*N16*M16))/(M16*12) -> 0
C18: Monthly Interest Saved from Refinancing | H18: =H11-H16 -> 0 | K18: Monthly Interest Saved from Refinancing | P18: =P11-P16 -> 0
C19: Total Interest Saving / Year | H19: =H18*12 -> 0 | K19: Total Interest Saving / Year | P19: =P18*12 -> 0
C20: Total Interest Save for n years | H20: =H19*E16 -> 0 | K20: Total Interest Save for n years | P20: =P19*M16 -> 0

Sheet Risk
B2: Risk Management | H2: Risk Management
D3: Age | J3: Age
C4: Self | D4: 50 | I4: Spouse | J4: 50
D5: Monthly (RM) | E5: n | F5: Yearly (RM) | J5: Monthly (RM) | K5: n | L5: Yearly (RM)
C6: Current Income of Self | D6: =CashFlow!C6/12 -> 4500 | E6: 12 | F6: =D6*E6 -> 54000
C7: Current Income of Spouse | D7: =CashFlow!D6/12 -> 4500 | E7: 12 | F7: =D7*E7 -> 54000 | I7: Current Income | J7: =D7 -> 4500 | K7: 12 | L7: =J7*K7 -> 54000
D8: Age | E8: Years Expectation | F8: Years of Coverage | L8: Years of Coverage
C9: Spouse | D9: 50 | E9: 100 | F9: =E9-D9 -> 50 | I9: Spouse | J9: 5 | K9: 25 | L9: 20
C10: Parents | D10: 80 | E10: 90 | F10: =E10-D10 -> 10 | I10: Children | J10: 5 | K10: 25 | L10: 20
C11: Required Current Income for Protection | E11: 1 | F11: =F6*E11 -> 54000 | I11: Required Current Income for Protection | K11: 1 | L11: =L7*K11 -> 54000
C12: Basing on Salary Increment as return on investment | E12: 0.05 | I12: Basing on Salary Increment as return on investment | K12: 0.05
C13: Basing Inflation | E13: 0.05 | I13: Basing Inflation | K13: 0.05
B14: n | C14: Growth (Living) | D14: Inflation | E14: PMT | F14: PV | H14: n | I14: Growth (Living) | J14: Inflation | K14: PMT | L14: PV
B15: =F9 -> 50 | C15: =E12 -> 0.05 | D15: =E13 -> 0.05 | E15: =F11 -> 54000 | F15: =PV((1+C15)/(1+D15)-1,B15,-E15) -> 2700000 | H15: 20 | I15: =K12 -> 0.05 | J15: =K13 -> 0.05 | K15: =L11 -> 54000 | L15: 3623126
B16: =F10 -> 10 | C16: =E12 -> 0.05 | D16: =E13 -> 0.05 | E16: 3500 | F16: =PV((1+C16)/(1+D16)-1,B16,-E16) -> 35000
D18: n | E18: Monthly | J18: n | K18: Monthly
B19: 1 | C19: 6 Months Family Expenses | D19: 12 | E19: =F11/12 -> 4500 | F19: =D19*E19 -> 54000 | H19: 1 | I19: 6 Months Family Expenses | J19: 6 | K19: 16667 | L19: 100000
B20: 2 | C20: Final Expense | F20: 20000 | H20: 2 | I20: Final Expense | L20: 20000
B21: 3 | C21: Outstanding Housing Loan (Balance) | F21: =Loan!G14 -> 0 | H21: 3 | I21: Outstanding Housing Loan (Balance) | J21: 33 | L21: 668093
B22: 4 | C22: Outstanding Car Loan (Balance) | F22: =Loan!O14 -> 0 | H22: 4 | I22: Outstanding Car Loan (Balance) | J22: 24 | L22: 26400
C23: Subtotal | F23: =SUM(F19:F22) -> 74000 | I23: Subtotal | L23: =SUM(L19:L22) -> 814493
C24: Total Insurance Needed | F24: =SUM(F23,F15) -> 2774000 | I24: Total Insurance Needed | L24: =SUM(L23,L15) -> 4437619
C26: Less Existing Insurance Protection | I26: Less Existing Insurance Protection
C27: ILP | F27: ='Net Worth'!C16 -> 679586.8 | I27: ILP | L27: 1500000
C28: PA | F28: ='Net Worth'!C9 -> 856000 | I28: PA
C29: Group Term | I29: Group Term
C30: EPF | F30: ='Net Worth'!C17 -> 513325.7 | I30: EPF | L30: 180000
C31: Investment Asset | F31: ='Net Worth'!C21 -> 3527719.6
C34: Subtotal | F34: =SUM(F27:F32) -> 5576632.1 | I34: Subtotal | L34: =SUM(L27:L30) -> 1680000
C35: Shortfall of Insurance | F35: =F24-F34 -> -2802632.1 | I35: Shortfall of Insurance | L35: =L24-L34 -> 2757619

Sheet Education
B2: Year to University (Year) | C2: Estimate Education Fund Needed Today (RM) | D2: Estimate Fund for Education at age 18 (RM) | E2: Education Fund Needed at age 18 (RM) | F2: Total Education Fund Needed | G2: Shortfall / Excess (RM)
B3: 12 | C3: 50,000 /yr | D3: 300000 | E3: 89793 | F3: 387017 | G3: =F3-D3 -> 87017
B7: Education Fund Needs (Canada)
B8: Chloe @ Age 19
C9: n | D9: i | E9: PV (RM) | F9: FV (RM) | H9: PMT | I9: i | J9: n
B10: 1st Year University | C10: 12 | D10: 0.05 | E10: 50000 | F10: 89792 | H10: 4381 | I10: 0.08 | J10: 12
B11: 2nd Year University | C11: 13 | D11: 0.05 | E11: 50000 | F11: 94282 | H11: 4061 | I11: 0.08 | J11: 13
B12: 3rd Year University | C12: 14 | D12: 0.05 | E12: 50000 | F12: 98997 | H12: 3785 | I12: 0.08 | J12: 14
B13: 4th Year University | C13: 15 | D13: 0.05 | E13: 50000 | F13: 103946 | H13: 3545 | I13: 0.08 | J13: 15
E14: Total | F14: =SUM(F10:F13) -> 387017 | H14: =SUM(H10:H13) -> 15772

Sheet Tax
B2: Income Tax Computations for the year of assessment 2024 | F2: Income Tax Computations for the year of assessment 2024
C3: SELF | D3: SPOUSE | G3: SELF | H3: SPOUSE
C4: RM | D4: RM | G4: RM | H4: RM
B5: Statutory Income | F5: Statutory Income
B6: Employment Income | C6: 54000 | D6: 54000 | F6: Employment Income | G6: 180000 | H6: 200000
B7: Rental | F7: Rental
B8: Aggregate Income | C8: =SUM(C6:C7) -> 54000 | D8: =SUM(D6:D7) -> 54000 | F8: Aggregate Income | G8: =SUM(G6:G7) -> 180000 | H8: =SUM(H6:H7) -> 200000
B10: (Approved Donations) | F10: (Approved Donations)
B12: Total Income | C12: =SUM(C8) -> 54000 | D12: =SUM(D8) -> 54000 | F12: Total Income | G12: =SUM(G8) -> 180000 | H12: =SUM(H8) -> 200000
B14: (Relief) | F14: (Relief)
B15: Personal | C15: 9000 | D15: 9000 | F15: Personal | G15: 9000 | H15: 9000
B16: Basic Supporting Equipment | F16: Basic Supporting Equipment
B17: Education Fees (self) | F17: Education Fees (self)
B18: Vaccination | F18: Vaccination
B19: Life Style | C19: 5000 | D19: 5000 | F19: Life Style | G19: 5000 | H19: 5000
B20: Childcare under 6 yearold | F20: Childcare under 6 yearold | H20: 3000
B21: SSPN | F21: SSPN | G21: 8000 | H21: 8000
B22: PRS | C22: 3000 | D22: 3000 | F22: PRS | G22: 3000 | H22: 3000
B23: Life Insurance | C23: 7000 | D23: 7000 | F23: Life Insurance | G23: 7000 | H23: 7000
B24: EPF | C24: 3000 | D24: 3000 | F24: EPF | G24: 3000 | H24: 3000
B25: Medical / Education Premium | C25: 3000 | D25: 3000 | F25: Medical / Education Premium | G25: 3000 | H25: 3000
B26: SOCSO | C26: 350 | D26: 350 | F26: SOCSO | G26: 350 | H26: 350
B27: Sport | C27: 500 | D27: 500 | F27: Sport | G27: 500 | H27: 500
B28: Books | F28: Books | G28: 2500 | H28: 2500
B29: Children (under 18) | F29: Children (under 18) | G29: 2000
B30: Children Education | F30: Children Education
B31: Vacation | C31: 1000 | D31: 1000 | F31: Vacation | G31: 1000 | H31: 1000
B33: Total Relief | C33: =SUM(C15:C31) -> 31850 | D33: =SUM(D15:D31) -> 31850 | F33: Total Relief | G33: =SUM(G15:G31) -> 44350 | H33: =SUM(H15:H31) -> 45350
B34: Taxable Income | C34: =C12-C33 -> 22150 | D34: =D12-D33 -> 22150 | F34: Taxable Income | G34: =G12-G33 -> 135650 | H34: =H12-H33 -> 154650
B36: Tax Payable | F36: Tax Payable
B37: On the 1st RM20,000 (Self) & RM20,000 (Spouse) | C37: 150 | D37: 150 | F37: On the 1st RM100,000 (Self) & RM100,000 (Spouse) | G37: 9400 | H37: 9400
B38: On Balance (3% of RM5,150) | C38: =(C34-20000)*0.03 -> 64.5 | D38: =(D34-20000)*0.03 -> 64.5 | F38: On Balance (25% of RM35,650) | G38: =(G34-100000)*0.25 -> 8912.5
F39: On Balance (25% of RM54,650) | H39: =(H34-100000)*0.254 -> 13881.1
B40: Total Tax Payable | C40: =SUM(C37:C39) -> 214.5 | D40: =SUM(D37:D39) -> 214.5 | F40: Total Tax Payable | G40: =SUM(G37:G39) -> 18312.5 | H40: =SUM(H37:H39) -> 23281.1
B41: Total Tax Payable (Joint) | D41: =SUM(C40:D40) -> 429 | F41: Total Tax Payable (Joint) | H41: =SUM(G40:H40) -> 41593.6

Sheet Retirement
G2: Retirement Sum Needed (RM) | I2: Current Fund Available (RM) | J2: Surplus / Shortfall (RM) | K2: Investment Rate of Return (%) | L2: Annual Investment (RM) | O2: Retirement Sum Needed (RM) | Q2: Current Fund Available (RM) | R2: Surplus / Shortfall (RM) | S2: Investment Rate of Return (%) | T2: Annual Investment (RM)
G3: =L29 -> 4079962 | I3: =L43 -> 21491520 | J3: =L44 -> -17411558 | K3: 8 | L3: =L46 -> -2748067.1 | O3: =T29 -> 10035768 | Q3: =T43 -> 10056510 | R3: =T44 -> -20742 | S3: 8 | T3: =T46 -> 513
C5: Self | D5: Spouse | F5: Retirement Planning | N5: Revised - Retirement Planning
B6: Annual retirement income needed if you retire today (Annual Salary x 100%) | C6: 54000 | D6: 54000 | H6: Age | I6: Retirement Age | J6: Year to Retirement | K6: Age at end of Retirement | L6: Length of Retirement | P6: Age | Q6: Retirement Age | R6: Year to Retirement | S6: Age at end of Retirement | T6: Length of Retirement
B7: Retirement Age | C7: 55 | D7: 55 | G7: Self | H7: 50 | I7: 55 | J7: =I7-H7 -> 5 | K7: 90 | L7: =K7-I7 -> 35 | O7: Mr. Choo | P7: 37 | Q7: 55 | R7: 18 | S7: 75 | T7: 20
B8: Current Age | C8: 50 | D8: 50 | G8: Spouse | H8: 50 | I8: 55 | J8: =I8-H8 -> 5 | K8: 90 | L8: =K8-I8 -> 35 | O8: Mrs. Khoo | P8: 37 | Q8: 55 | R8: 18 | S8: 75 | T8: 20
B9: Year to Retirement | C9: 5 | D9: 5 | H9: Monthly | I9: Month | J9: Annual | K9: % | L9: Amount (RM) | P9: Monthly | Q9: Month | R9: Annual | S9: % | T9: Amount (RM)
B10: Life Style Inflation rate (i) | C10: 0.05 | D10: 0.05 | F10: E | G10: Current Salary of Self | H10: 4500 | I10: 12 | J10: =H10*I10 -> 54000 | N10: E | O10: Current Salary of Mrs. Ewe | P10: 15000 | Q10: 12 | R10: 180000
B11: Annual Income on1st year of retirement (PMT) at age55 | C11: 433191 | D11: 481324 | F11: E | G11: Required Salary for Retirement | K11: 100 | L11: =J10 -> 54000 | N11: E | O11: Required Salary for Retirement | S11: 100 | T11: 180000
B12: Retirement years after Age55 (n) (80– 55) | C12: 25 | D12: 25 | F12: K | G12: Current Salary of Spouse | H12: 4500 | I12: 12 | J12: =H12*I12 -> 54000 | N12: K | O12: Current Salary of Mr. Khoo | P12: 16667 | Q12: 12 | R12: 200000
B13: Rate of return during retirement (r) | C13: 0.05 | D13: 0.05 | F13: K | G13: Required Salary for Retirement | K13: 100 | L13: =J12 -> 54000 | N13: K | O13: Required Salary for Retirement | S13: 100 | T13: 200000
B14: Inflation | C14: 0.04 | D14: 0.04 | G14: Salary Increment | K14: 5 | O14: Salary Increment | S14: 5
B15: Adjusted rate of return i=(0.05– 0.04)/1.04 | C15: =(0.05-0.04)/1.04 -> 0.0096153846 | D15: =(0.05-0.04)/1.04 -> 0.0096153846 | G15: Inflation | K15: 4 | O15: Inflation | S15: 4
B16: Total Retirement Fund required (PV) BGN | C16: 7924093 | D16: 8804541 | G16: Return on Investment on Retirement | K16: 5 | O16: Return on Investment on Retirement | S16: 5
B17: Total Retirement Fund for Mr. & Mrs. Choo | D17: =SUM(C16:D16) -> 16728634 | G17: Return on Retirement Provident Fund | K17: 8 | O17: Return on Retirement Provident Fund | S17: 8
G18: Property Appreciation Rate | K18: 8 | O18: Property Appreciation Rate | S18: 8
H20: n | I20: Growth (%) | J20: Inflation (%) | K20: PV (RM) | L20: FV (RM) | P20: n | Q20: Growth (%) | R20: Inflation (%) | S20: PV (RM) | T20: FV (RM)
F21: E | G21: Last Drawn Salary at Retirement | H21: =J7 -> 5 | I21: 5 | K21: 54000 | L21: =FV(I21/100,H21,0,-K21) -> 68919.204 | N21: E | O21: Last Drawn Salary at Retirement | P21: 18 | Q21: 5 | S21: 180000 | T21: 433191
F22: E | G22: Last Drawn Salary at Retirement (100%) | H22: =J7 -> 5 | I22: 5 | K22: 54000 | L22: =FV(I22/100,H22,0,-K22) -> 68919.204 | N22: E | O22: Last Drawn Salary at Retirement (60%) | P22: 18 | Q22: 5 | S22: 108000 | T22: 259914
K23: PMT (RM) | L23: PV (RM) | S23: PMT (RM) | T23: PV (RM)
F24: E | G24: Retirement Capital Required | H24: =L7 -> 35 | I24: 5 | J24: 4 | K24: 68919 | L24: =PV(((I24-J24)/100)/(1+(J24/100)),H24,-K24,0) -> 2039981 | N24: E | O24: Retirement Capital Required | P24: 20 | Q24: 5 | R24: 4 | S24: =T22 -> 259914 | T24: 4753779
F25: K | G25: Last Drawn Salary at Retirement | H25: =J8 -> 5 | I25: 5 | K25: 54000 | L25: =FV(I25/100,H25,0,-K25) -> 68919.204 | N25: K | O25: Last Drawn Salary at Retirement | P25: 18 | Q25: 5 | S25: 200000 | T25: 481324
F26: K | G26: Last Drawn Salary at Retirement (100%) | H26: =J8 -> 5 | I26: 5 | K26: 54000 | L26: =FV(I26/100,H26,0,-K26) -> 68919.204 | N26: K | O26: Last Drawn Salary at Retirement (60%) | P26: 18 | Q26: 5 | S26: 120000 | T26: 288794
K27: PMT (RM) | L27: PV (RM) | S27: PMT (RM) | T27: PV (RM)
F28: K | G28: Retirement Capital Required | H28: =L8 -> 35 | I28: 5 | J28: 4 | K28: 68919 | L28: =PV(((I28-J28)/100)/(1+(J28/100)),H28,-K28,0) -> 2039981 | N28: K | O28: Retirement Capital Required | P28: 20 | Q28: 5 | R28: 4 | S28: =T26 -> 288794 | T28: 5281989
G29: Total Lump Sum Retirement Capital Requirement for Both | L29: =SUM(L24,L28) -> 4079962 | O29: Total Lump Sum Retirement Capital Requirement for Both | T29: =SUM(T24,T28) -> 10035768
G30: Total Resources | K30: PV | L30: FV | O30: Total Resources | S30: PV | T30: FV
G31: Properties | H31: =$J$7 -> 5 | I31: 8 | K31: =Investment!C17 -> 10047200 | L31: =FV(I31/100,H31,0,-(K31)) -> 14762633 | O31: Properties | P31: 18 | Q31: 8
G32: Fixed Deposit Joint) | H32: =$J$7 -> 5 | I32: 3 | K32: =Investment!C5 -> 0 | L32: =FV(I32/100,H32,0,-(K32)) -> 0 | O32: Fixed Deposit (Joint) | P32: 18 | Q32: 3 | S32: 31000 | T32: 52775
G33: Life Ins CSV | H33: =$J$7 -> 5 | I33: 5 | K33: =Investment!C6 -> 856000 | L33: =FV(I33/100,H33,0,-(K33)) -> 1092497 | O33: Life Ins CSV
G34: Equities | H34: =$J$7 -> 5 | I34: 8 | K34: =Investment!C8 -> 434790.66 | L34: =FV(I34/100,H34,0,-(K34)) -> 638850.12 | O34: Equities | P34: 18 | Q34: 8 | S34: 400000 | T34: 1598408
G35: Bonds | H35: =$J$7 -> 5 | I35: 4 | K35: =Investment!C9 -> 317422.14 | L35: =FV(I35/100,H35,0,-(K35)) -> 386192.57 | O35: Bonds | P35: 18 | Q35: 4 | S35: 100000 | T35: 202582
G36: Unit Trust | H36: =$J$7 -> 5 | I36: 8 | K36: =Investment!C10 -> 1604418.1 | L36: =FV(I36/100,H36,0,-(K36)) -> 2357416.5 | O36: Unit Trust | P36: 18 | Q36: 8 | S36: 290000 | T36: 1158846
G37: PRS | H37: =$J$7 -> 5 | I37: 8 | K37: =Investment!C11 -> 137324 | L37: =FV(I37/100,H37,0,-(K37)) -> 201774.01 | O37: PRS | P37: 18 | Q37: 8 | S37: 48000 | T37: 191808
G38: ILP (Joint) | H38: =$J$7 -> 5 | I38: 5 | K38: =Investment!C12 -> 751324 | L38: =FV(I38/100,H38,0,-(K38)) -> 958900.97 | O38: ILP (Joint) | P38: 18 | S38: 1940000 | T38: 1940000
G39: EPF (Joint) | H39: =$J$7 -> 5 | I39: 6 | K39: =Investment!C16 -> 701964.7 | L39: =FV(I39/100,H39,0,-(K39)) -> 939387.12 | O39: EPF (Joint) | P39: 18 | Q39: 6 | S39: 350000 | T39: 999019
H40: n | I40: Growth | J40: Salary | K40: PMT | L40: FV | P40: n | Q40: Growth | R40: Salary | S40: PMT | T40: FV
F41: E | G41: FV of Accumulation EPF | H41: =J7 -> 5 | I41: 6 | J41: 5 | K41: =K21*0.23 -> 12420 | L41: =K41*((((1+(J41/100))^H41)-((1+(I41/100)))^H41))/((J41/100)-(I41/100)) -> 76934.467 | N41: E | O41: FV of Accumulation EPF | P41: 18 | Q41: 6 | R41: 5 | S41: 41400 | T41: 1853560
F42: K | G42: FV of Accumulation EPF | H42: =J8 -> 5 | I42: 6 | J42: 5 | K42: =K25*0.23 -> 12420 | L42: =K42*((((1+(J42/100))^H42)-((1+(I42/100)))^H42))/((J42/100)-(I42/100)) -> 76934.467 | N42: K | O42: FV of Accumulation EPF | P42: 18 | Q42: 6 | R42: 5 | S42: 46000 | T42: 2059512
G43: Total Resource | L43: =SUM(L31:L39,L41:L42) -> 21491520 | O43: Total Resource | T43: =SUM(T31:T39,T41:T42) -> 10056510
...

Sheet Investment
H1: Revised - Investment Planning – Current Onvestment Portfolio
B2: Investment Planning – Current Onvestment Portfolio | I2: Self | M2: Spouse
B3: Current Assets | C3: Amount (RM) | D3: Weight | E3: Rate of Return (%) | F3: Weighted ROI | H3: Current Assets | I3: Amount (RM) | J3: Weight | K3: Rate of Return (%) | L3: Weighted ROI | M3: Amount (RM) | N3: Weight | O3: Rate of Return (%) | P3: Weighted ROI
B4: Saving Account | C4: =SUM('Net Worth'!E6:E7) -> 2243306.3 | D4: =C4/$C$19 -> 0.13123547 | E4: 2 | F4: =D4*E4 -> 0.26247094 | H4: Saving Account | I4: =P42+P66 -> 578940.03 | J4: =I4/$I$19 -> 0.041911042 | K4: 2 | L4: =J4*K4 -> 0.083822085 | M4: =Q42+Q66 -> 239784.33 | N4: =M4/$I$19 -> 0.01735864 | O4: 2 | P4: =N4*O4 -> 0.034717279
B5: Fixed Deposit | C5: ='Net Worth'!E8 -> 0 | D5: =C5/$C$19 -> 0 | E5: 2 | F5: =D5*E5 -> 0 | H5: Fixed Deposit | I5: =P65 -> 0 | J5: =I5/$I$19 -> 0 | K5: 3 | L5: =J5*K5 -> 0 | M5: =Q65 -> 56546.1 | N5: =M5/$I$19 -> 0.0040935259 | O5: 3 | P5: =N5*O5 -> 0.012280578
B6: Life Ins. CSV | C6: ='Net Worth'!E9 -> 856000 | D6: =C6/$C$19 -> 0.050076783 | E6: 5 | F6: =D6*E6 -> 0.25038391 | H6: Life Ins. CSV | I6: 0 | J6: =I6/$I$19 -> 0 | K6: 5 | L6: =J6*K6 -> 0 | M6: 0 | N6: =M6/$I$19 -> 0 | O6: 5 | P6: =N6*O6 -> 0
B7: Saving Account (Children) | C7: ='Net Worth'!E10 -> 0 | D7: =C7/$C$19 -> 0 | E7: 2 | F7: =D7*E7 -> 0 | H7: Saving Account (Children) (SPNN) | I7: 0 | J7: =I7/$I$19 -> 0 | K7: 4 | L7: =J7*K7 -> 0 | M7: 0 | N7: =M7/$I$19 -> 0 | O7: 4 | P7: =N7*O7 -> 0
B8: Equities | C8: ='Net Worth'!E13 -> 434790.66 | D8: =C8/$C$19 -> 0.025435651 | E8: 8 | F8: =D8*E8 -> 0.20348521 | H8: Equities | I8: =P41+P101 -> 562811.86 | J8: =I8/$I$19 -> 0.040743481 | K8: 8 | L8: =J8*K8 -> 0.32594784 | M8: =Q41+Q101 -> 218486.3 | N8: =M8/$I$19 -> 0.015816817 | O8: 8 | P8: =N8*O8 -> 0.12653454
B9: Bonds | C9: ='Net Worth'!E14 -> 317422.14 | D9: =C9/$C$19 -> 0.018569486 | E9: 4 | F9: =D9*E9 -> 0.074277942 | H9: Bonds | I9: =P44 -> 1199433.8 | J9: =I9/$I$19 -> 0.086830274 | K9: 4 | L9: =J9*K9 -> 0.3473211 | M9: =Q44 -> 0 | N9: =M9/$I$19 -> 0 | O9: 4 | P9: =N9*O9 -> 0
B10: Unit Trust | C10: ='Net Worth'!E15 -> 1604418.1 | D10: =C10/$C$19 -> 0.093859924 | E10: 8 | F10: =D10*E10 -> 0.75087939 | H10: Unit Trust | I10: =P39 -> 1483731.4 | J10: =I10/$I$19 -> 0.10741135 | K10: 7 | L10: =J10*K10 -> 0.75187942 | M10: =Q39 -> 39709.19 | N10: =M10/$I$19 -> 0.0028746562 | O10: 7 | P10: =N10*O10 -> 0.020122593
B11: PRS | C11: ='Net Worth'!E18 -> 137324 | D11: =C11/$C$19 -> 0.0080335796 | E11: 8 | F11: =D11*E11 -> 0.064268637 | H11: PRS | I11: =P43 -> 82700.95 | J11: =I11/$I$19 -> 0.0059869466 | K11: 8 | L11: =J11*K11 -> 0.047895572 | M11: =Q43 -> 62343.94 | N11: =M11/$I$19 -> 0.0045132473 | O11: 8 | P11: =N11*O11 -> 0.036105978
B12: ILP | C12: ='Net Worth'!E16 -> 751324 | D12: =C12/$C$19 -> 0.043953141 | E12: 5 | F12: =D12*E12 -> 0.21976571 | H12: ILP | I12: =P40 -> 1277078.3 | J12: =I12/$I$19 -> 0.092451171 | K12: 5 | L12: =J12*K12 -> 0.46225586 | M12: =Q40 -> 0 | N12: =M12/$I$19 -> 0 | O12: 5 | P12: =N12*O12 -> 0
B13: ILP (Children) | C13: ='Net Worth'!E20 -> 0 | D13: =C13/$C$19 -> 0 | E13: 5 | F13: =D13*E13 -> 0 | H13: ILP (Children) | I13: 0 | J13: =I13/$I$19 -> 0 | K13: 5 | L13: =J13*K13 -> 0 | M13: 0 | N13: =M13/$I$19 -> 0 | O13: 5 | P13: =N13*O13 -> 0
B14: Subtotal | C14: =SUM(C4:C13) -> 6344585.1 | D14: =C14/C19 -> 0.37116403 | F14: =SUM(F4:F13) -> 1.8255317 | H14: Subtotal | I14: =SUM(I4:I13) -> 5184696.4 | J14: =I14/I19 -> 0.37533426 | L14: =SUM(L4:L13) -> 2.0191219 | M14: =SUM(M4:M13) -> 616869.86 | N14: =M14/M19 -> 0.22769537 | P14: =SUM(P4:P13) -> 0.22976097
B15: Fixed Assets | H15: Fixed Assets
B16: EPF | C16: ='Net Worth'!E17 -> 701964.7 | D16: =C16/$C$19 -> 0.041065577 | E16: 6 | F16: =D16*E16 -> 0.24639346 | H16: EPF | I16: =P67 -> 478847.7 | J16: =I16/$I$19 -> 0.034665087 | K16: 5 | L16: =J16*K16 -> 0.17332543 | M16: =Q67 -> 195119.46 | N16: =M16/$I$19 -> 0.014125228 | O16: 5 | P16: =N16*O16 -> 0.07062614
B17: Properties | C17: ='Net Worth'!E23 -> 10047200 | D17: =C17/$C$19 -> 0.58777039 | E17: 8 | F17: =D17*E17 -> 4.7021631 | H17: Properties | I17: ='Net Worth'!C23 -> 8150000 | J17: =I17/$I$19 -> 0.59000065 | K17: 8 | L17: =J17*K17 -> 4.7200052 | M17: ='Net Worth'!D23 -> 1897200 | N17: =M17/$I$19 -> 0.13734346 | O17: 8 | P17: =N17*O17 -> 1.0987477
B18: Subtotal | C18: =SUM(C16:C17) -> 10749165 | D18: =C18/C19 -> 0.62883597 | F18: =SUM(F16:F17) -> 4.9485566 | H18: Subtotal | I18: =SUM(I16:I17) -> 8628847.7 | J18: =I18/I19 -> 0.62466574 | L18: =SUM(L16:L17) -> 4.8933307 | M18: =SUM(M16:M17) -> 2092319.5 | N18: =M18/M19 -> 0.77230463 | P18: =SUM(P16:P17) -> 1.1693739
B19: Grand Total | C19: =SUM(C14,C18) -> 17093750 | D19: 1 | F19: =SUM(F14,F18) -> 6.7740883 | H19: Grand Total | I19: =SUM(I14,I18) -> 13813544 | J19: 1 | L19: =SUM(L14,L18) -> 6.9124525 | M19: =SUM(M14,M18) -> 2709189.3 | N19: 1 | P19: =SUM(P14,P18) -> 1.3991348
B23: Investment | C23: Buying | D23: In MYR | E23: Market Value | F23: % | G23: In Original | H23: Location | I23: Remark | J23: 2034 | K23: Muture | L23: Type | N23: Location | O23: Exchange
A24: Self | B24: Shariah Gold - SGTF | C24: 60952.72 | D24: =IF(H24="MY", C24, C24 * VLOOKUP(H24, $N$24:$O$32, 2, FALSE)) -> 60952.72 | E24: =IF(H24="MY", G24, G24 * VLOOKUP(H24, $N$24:$O$32, 2, FALSE)) -> 60382.47 | F24: =(G24/C24)-1 -> -0.009355612 | G24: 60382.47 | H24: MY | L24: UT | N24: MY | O24: 1
A25: Self | B25: China A Opportunity - CAOFMYRH | C25: 227225.82 | D25: =IF(H25="MY", C25, C25 * VLOOKUP(H25, $N$24:$O$32, 2, FALSE)) -> 227225.82 | E25: =IF(H25="MY", G25, G25 * VLOOKUP(H25, $N$24:$O$32, 2, FALSE)) -> 212135.17 | F25: =(G25/C25)-1 -> -0.066412567 | G25: 212135.17 | H25: MY | L25: UT | N25: HK | O25: 0.5295
A26: Self | B26: Global Infrastructure - GINFIMYRH | C26: 100192 | D26: =IF(H26="MY", C26, C26 * VLOOKUP(H26, $N$24:$O$32, 2, FALSE)) -> 100192 | E26: =IF(H26="MY", G26, G26 * VLOOKUP(H26, $N$24:$O$32, 2, FALSE)) -> 97314.68 | F26: =(G26/C26)-1 -> -0.028718061 | G26: 97314.68 | H26: MY | L26: UT | N26: US | O26: 4.1189
A27: Self | B27: UOB - Pruenrich Gain 31442809 | C27: 301407 | D27: =IF(H27="MY", C27, C27 * VLOOKUP(H27, $N$24:$O$32, 2, FALSE)) -> 301407 | E27: =IF(H27="MY", G27, G27 * VLOOKUP(H27, $N$24:$O$32, 2, FALSE)) -> 299257 | F27: =(G27/C27)-1 -> -0.0071332119 | G27: 299257 | H27: MY | I27: Muture - 15yrs | J27: 376428 | K27: 471164 | L27: ILP | N27: SG | O27: 3.1795
A28: Self | B28: PMO - Public Equity 023552684 | C28: 17000 | D28: =IF(H28="MY", C28, C28 * VLOOKUP(H28, $N$24:$O$32, 2, FALSE)) -> 17000 | E28: =IF(H28="MY", G28, G28 * VLOOKUP(H28, $N$24:$O$32, 2, FALSE)) -> 24004.1 | F28: =(G28/C28)-1 -> 0.41200588 | G28: 24004.1 | H28: MY | L28: EQ | N28: UK | O28: 5.488
A29: Self | B29: PMO - Public Regular Saving | C29: 10000 | D29: =IF(H29="MY", C29, C29 * VLOOKUP(H29, $N$24:$O$32, 2, FALSE)) -> 10000 | E29: =IF(H29="MY", G29, G29 * VLOOKUP(H29, $N$24:$O$32, 2, FALSE)) -> 19043.46 | F29: =(G29/C29)-1 -> 0.904346 | G29: 19043.46 | H29: MY | L29: UT | N29: CN | O29: 0.58
A30: Self | B30: KL Exchg (Saving-HKD) | C30: 23811.77 | D30: =IF(H30="MY", C30, C30 * VLOOKUP(H30, $N$24:$O$32, 2, FALSE)) -> 12608.332 | E30: =IF(H30="MY", G30, G30 * VLOOKUP(H30, $N$24:$O$32, 2, FALSE)) -> 12608.332 | F30: =(G30/C30)-1 -> 0 | G30: 23811.77 | H30: HK | L30: S | N30: TH | O30: 0.1295
A31: Self | B31: KL Exchg (Saving-USD) | C31: 1392.27 | D31: =IF(H31="MY", C31, C31 * VLOOKUP(H31, $N$24:$O$32, 2, FALSE)) -> 5734.6209 | E31: =IF(H31="MY", G31, G31 * VLOOKUP(H31, $N$24:$O$32, 2, FALSE)) -> 5734.6209 | F31: =(G31/C31)-1 -> 0 | G31: 1392.27 | H31: US | L31: S | N31: AU | O31: 2.2782
A32: Self | B32: PRS - AIA PAM Growth Fund | C32: 34836.38 | D32: =IF(H32="MY", C32, C32 * VLOOKUP(H32, $N$24:$O$32, 2, FALSE)) -> 34836.38 | E32: =IF(H32="MY", G32, G32 * VLOOKUP(H32, $N$24:$O$32, 2, FALSE)) -> 41906.31 | F32: =(G32/C32)-1 -> 0.20294675 | G32: 41906.31 | H32: MY | I32: 1500 | L32: PRS | N32: TW | O32: 0.132
A33: Self | B33: PRS - AIA PAM Conservative Fund | C33: 33082.58 | D33: =IF(H33="MY", C33, C33 * VLOOKUP(H33, $N$24:$O$32, 2, FALSE)) -> 33082.58 | E33: =IF(H33="MY", G33, G33 * VLOOKUP(H33, $N$24:$O$32, 2, FALSE)) -> 40794.64 | F33: =(G33/C33)-1 -> 0.23311543 | G33: 40794.64 | H33: MY | I33: 1500 | L33: PRS
A34: Self | B34: CIMB - Sun Ins L9774039 | C34: 20000 | D34: =IF(H34="MY", C34, C34 * VLOOKUP(H34, $N$24:$O$32, 2, FALSE)) -> 20000 | E34: =IF(H34="MY", G34, G34 * VLOOKUP(H34, $N$24:$O$32, 2, FALSE)) -> 9424.46 | F34: =(G34/C34)-1 -> -0.528777 | G34: 9424.46 | H34: MY | I34: Muture - 20yrs | J34: =95000+7000 -> 102000 | K34: =83000+20000 -> 103000 | L34: ILP
A35: Self | B35: HSBC - Ins UniversalIncome 9110023977 | C35: 150000 | D35: =IF(H35="MY", C35, C35 * VLOOKUP(H35, $N$24:$O$32, 2, FALSE)) -> 150000 | E35: =IF(H35="MY", G35, G35 * VLOOKUP(H35, $N$24:$O$32, 2, FALSE)) -> 157257.21 | F35: =(G35/C35)-1 -> 0.0483814 | G35: 157257.21 | H35: MY | L35: ILP
A36: Self | B36: HSBC - Ins UniversalIncome 9110045587 | C36: 150000 | D36: =IF(H36="MY", C36, C36 * VLOOKUP(H36, $N$24:$O$32, 2, FALSE)) -> 150000 | E36: =IF(H36="MY", G36, G36 * VLOOKUP(H36, $N$24:$O$32, 2, FALSE)) -> 152430.81 | F36: =(G36/C36)-1 -> 0.0162054 | G36: 152430.81 | H36: MY | L36: ILP
A37: Self | B37: HSBC - Ins EliteSaver 9110125246 | D37: =IF(H37="MY", C37, C37 * VLOOKUP(H37, $N$24:$O$32, 2, FALSE)) -> 0 | E37: =IF(H37="MY", G37, G37 * VLOOKUP(H37, $N$24:$O$32, 2, FALSE)) -> 41267.59 | F37: =(E37/C37)-1 -> #DIV/0! | G37: 41267.59 | H37: MY | L37: ILP
A38: Self | B38: HSBC - Ins EliteCare Plus 9110170036 | D38: =IF(H38="MY", C38, C38 * VLOOKUP(H38, $N$24:$O$32, 2, FALSE)) -> 0 | E38: =IF(H38="MY", G38, G38 * VLOOKUP(H38, $N$24:$O$32, 2, FALSE)) -> 37441.26 | F38: =(E38/C38)-1 -> #DIV/0! | G38: 37441.26 | H38: MY | L38: ILP | N38: Type | O38: Total | P38: Self | Q38: Spouse | R38: Total
A39: Self | B39: HSBC - AHAM World Series UAHAEFSGDH | C39: 24000 | D39: =IF(H39="MY", C39, C39 * VLOOKUP(H39, $N$24:$O$32, 2, FALSE)) -> 76308 | E39: =IF(H39="MY", G39, G39 * VLOOKUP(H39, $N$24:$O$32, 2, FALSE)) -> 85110.382 | F39: =(G39/C39)-1 -> 0.11535333 | G39: 26768.48 | H39: SG | L39: UT | N39: UT | O39: =SUMIFS($E$24:$E$58, $L$24:$L$58, N39) -> 1523440.6 | P39: =SUMIFS($E$24:$E$58, $L$24:$L$58, N39, $A$24:$A$58, "Self") -> 1483731.4 | Q39: =SUMIFS($E$24:$E$58, $L$24:$L$58, N39, $A$24:$A$58, "Spouse") -> 39709.19 | R39: =SUM(P39:Q39) -> 1523440.6
A40: Self | B40: HSBC - Principle Global SC Bond UPGSCBFGHU | C40: 4900 | D40: =IF(H40="MY", C40, C40 * VLOOKUP(H40, $N$24:$O$32, 2, FALSE)) -> 26891.2 | E40: =IF(H40="MY", G40, G40 * VLOOKUP(H40, $N$24:$O$32, 2, FALSE)) -> 26459.788 | F40: =(G40/C40)-1 -> -0.016042857 | G40: 4821.39 | H40: UK | L40: B | N40: ILP | O40: =SUMIFS($E$24:$E$58, $L$24:$L$58, N40) -> 1277078.3 | P40: =SUMIFS($E$24:$E$58, $L$24:$L$58, N40, $A$24:$A$58, "Self") -> 1277078.3 | Q40: =SUMIFS($E$24:$E$58, $L$24:$L$58, N40, $A$24:$A$58, "Spouse") -> 0 | R40: =SUM(P40:Q40) -> 1277078.3
A41: Self | B41: HSBC - AHAM WS UAHGHSSGDH | C41: 50000 | D41: =IF(H41="MY", C41, C41 * VLOOKUP(H41, $N$24:$O$32, 2, FALSE)) -> 158975 | E41: =IF(H41="MY", G41, G41 * VLOOKUP(H41, $N$24:$O$32, 2, FALSE)) -> 167748.67 | F41: =(G41/C41)-1 -> 0.055189 | G41: 52759.45 | H41: SG | L41: UT | N41: EQ | O41: =SUMIFS($E$24:$E$58, $L$24:$L$58, N41) -> 257003.9 | P41: =SUMIFS($E$24:$E$58, $L$24:$L$58, N41, $A$24:$A$58, "Self") -> 257003.9 | Q41: =SUMIFS($E$24:$E$58, $L$24:$L$58, N41, $A$24:$A$58, "Spouse") -> 0 | R41: =SUM(P41:Q41) -> 257003.9
A42: Self | B42: HSBC - Principle Global SC Bond UPGSCBFUSU | C42: 20000 | D42: =IF(H42="MY", C42, C42 * VLOOKUP(H42, $N$24:$O$32, 2, FALSE)) -> 82378 | E42: =IF(H42="MY", G42, G42 * VLOOKUP(H42, $N$24:$O$32, 2, FALSE)) -> 81111.974 | F42: =(G42/C42)-1 -> -0.0153685 | G42: 19692.63 | H42: US | L42: B | N42: S | O42: =SUMIFS($E$24:$E$58, $L$24:$L$58, N42) -> 48723.803 | P42: =SUMIFS($E$24:$E$58, $L$24:$L$58, N42, $A$24:$A$58, "Self") -> 18342.953 | Q42: =SUMIFS($E$24:$E$58, $L$24:$L$58, N42, $A$24:$A$58, "Spouse") -> 30380.85 | R42: =SUM(P42:Q42) -> 48723.803
A43: Self | B43: HSBC - AHAM World Series UAHWSIFSHU | C43: 50000 | D43: =IF(H43="MY", C43, C43 * VLOOKUP(H43, $N$24:$O$32, 2, FALSE)) -> 158975 | E43: =IF(H43="MY", G43, G43 * VLOOKUP(H43, $N$24:$O$32, 2, FALSE)) -> 162509.11 | F43: =(G43/C43)-1 -> 0.0222306 | G43: 51111.53 | H43: SG | L43: UT | N43: PRS | O43: =SUMIFS($E$24:$E$58, $L$24:$L$58, N43) -> 145044.89 | P43: =SUMIFS($E$24:$E$58, $L$24:$L$58, N43, $A$24:$A$58, "Self") -> 82700.95 | Q43: =SUMIFS($E$24:$E$58, $L$24:$L$58, N43, $A$24:$A$58, "Spouse") -> 62343.94 | R43: =SUM(P43:Q43) -> 145044.89
...

Sheet Fin Ratio
B2: Financial Ratios – Mr. Choo and Mrs. Khoo
B3: 1 | C3: Basic Liquidity Ratio | D3: Total Current Asset | E3: Monthly Expenses
C4: Cash/Cash Equivalents / Monthly Expenses | D4: ='Net Worth'!E11 -> 3099306.3 | E4: =CashFlow!F39 -> 16364.96 | F4: =D4/E4 -> 189.38673
C5: Benchmark | F5: 3 – 6
B6: 2 | C6: Standby Liquidity Ratio | D6: Liquid Investment Asset | E6: Monthly Expenses
C7: Total Liquid Investment / MOnthly Expenses | D7: =SUM('Net Worth'!E11,'Net Worth'!E16) -> 3850630.3 | E7: =CashFlow!F39 -> 16364.96 | F7: =D7/E7 -> 235.29726
C8: Benchmark | F8: 3 – 6
B9: 3 | C9: Saving Ratio | D9: Saving | E9: Gross Income | F9: %
C10: Saving / Total Income | D10: =CashFlow!E23 -> 0 | E10: =CashFlow!F17 -> 19705 | F10: =D10/E10 -> 0
C11: Benchmark (min) | F11: 10
B12: 4 | C12: Liquid Asset to Net Worth Ratio | D12: Cash + Cash Equivalent | E12: Net Worth | F12: %
C13: Cash/Cash Equivalents / Net Worth | D13: ='Net Worth'!E11 -> 3099306.3 | E13: ='Net Worth'!M16 -> 17263140 | F13: =D13/E13 -> 0.17953317
C14: Benchmark (min) | F14: 15
B15: 5 | C15: Debt to Asset Ratio | D15: Total Debt | E15: Total Asset | F15: %
C16: Total Liabilities / Total Asset | D16: ='Net Worth'!M15 -> 610 | E16: ='Net Worth'!E29 -> 17263750 | F16: =D16/E16 -> 3.5334154e-05
C17: Benchmark (below) | F17: 50
B18: 6 | C18: Debt Services Ratio | D18: Total Monthly Loan Repayment | E18: Monthly Take Home Income | F18: %
C19: Monthly Total Loan Payment / Monthly Take Home Income | D19: =SUM(CashFlow!E20,CashFlow!E21,CashFlow!E22)/12 -> 0 | E19: =(CashFlow!E17-CashFlow!E10-CashFlow!E37)/12 -> 18664.167 | F19: =D19/E19 -> 0
C20: Benchmark (below) | F20: 35
B21: 7 | C21: Non Mortgage Debt Services Ratio | D21: Total Annual Non Mortgage Loan Repayment | E21: Total Annual Take Home Income | F21: %
C22: Total Loan Payment (non mortgage) / Total Take Home Income | D22: =CashFlow!E22 -> 0 | E22: =(CashFlow!E17-CashFlow!E10-CashFlow!E37) -> 223970 | F22: =D22/E22 -> 0
C23: Benchmark (below) | F23: 15
B24: 8 | C24: Net Investment Assets to Net Worth Ratio | D24: Net Investment asset | E24: Net Worth | F24: %
C25: Net Investment Assets / Net Worth | D25: ='Net Worth'!E21 -> 3947243.6 | E25: ='Net Worth'!M16 -> 17263140 | F25: =D25/E25 -> 0.22865154
C26: Benchmark (above) | F26: 35
B27: 9 | C27: Solvency Ratio | D27: Total Net Worth | E27: Total Asset | F27: %
C28: Total Net Worth / Total Asset | D28: ='Net Worth'!M16 -> 17263140 | E28: ='Net Worth'!E29 -> 17263750 | F28: =D28/E28 -> 0.99996467
C29: Benchmark (above) | F29: 50

Sheet Coverage
B3: Insurance # | C3: Sum Assured (Upon Death) | D3: Disability | E3: Critical Illness (CLR) | F3: Multiple Critical Illiness (CLR) | G3: Hospitalization | H3: Annual Hospital Limit | I3: Surrender Value | J3: Premium
B4: U570219415 | C4: 6000 | D4: 6000 | I4: 1328.65 | J4: 0
B5: 0191924A07 | C5: 6000 | D5: 6000 | I5: 1382.58 | J5: 0
B6: 5480488A10 | C6: 70000 | D6: 70000 | I6: 149484.48 | J6: =10634.76*2 -> 21269.52
B7: W574660992 | C7: 77500 | D7: 77500 | I7: 122839.73 | J7: 0
B8: 4170883A10 | C8: 6000 | D8: 6000 | I8: 1087.83 | J8: 0
B9: 0294117J04 | C9: 50000 | D9: 50000 | E9: 50000 | F9: 50000 | G9: 200 | H9: 10000000 | I9: 3625.01 | J9: 6800
B11: W573847185 | C11: 32000 | D11: 32000 | J11: 0
B12: 4170877A02 | C12: 6000 | D12: 6000 | I12: 802.77 | J12: 0
B13: 0294119J09 | C13: 50000 | D13: 50000 | E13: 50000 | F13: 50000 | G13: 200 | H13: 10000000 | I13: 3089.04 | J13: 5900
B15: 31442809
